Failure # 1 (occurred at 2023-04-28_12-59-01)
Traceback (most recent call last):
  File "C:\Users\Karthikeyan\anaconda3\lib\site-packages\ray\tune\trial_runner.py", line 886, in _process_trial
    results = self.trial_executor.fetch_result(trial)
  File "C:\Users\Karthikeyan\anaconda3\lib\site-packages\ray\tune\ray_trial_executor.py", line 675, in fetch_result
    result = ray.get(trial_future[0], timeout=DEFAULT_GET_TIMEOUT)
  File "C:\Users\Karthikeyan\anaconda3\lib\site-packages\ray\_private\client_mode_hook.py", line 105, in wrapper
    return func(*args, **kwargs)
  File "C:\Users\Karthikeyan\anaconda3\lib\site-packages\ray\worker.py", line 1765, in get
    raise value
  File "python\ray\_raylet.pyx", line 774, in ray._raylet.task_execution_handler
  File "python\ray\_raylet.pyx", line 595, in ray._raylet.execute_task
  File "python\ray\_raylet.pyx", line 737, in ray._raylet.execute_task
ray.exceptions.RayActorError: The actor died because of an error raised in its creation task, [36mray::PPOTrainer.__init__()[39m (pid=23224, ip=127.0.0.1, repr=PPOTrainer)
  File "python\ray\_raylet.pyx", line 640, in ray._raylet.execute_task
  File "python\ray\_raylet.pyx", line 644, in ray._raylet.execute_task
  File "python\ray\_raylet.pyx", line 593, in ray._raylet.execute_task.function_executor
  File "C:\Users\Karthikeyan\anaconda3\lib\site-packages\ray\_private\function_manager.py", line 648, in actor_method_executor
    return method(__ray_actor, *args, **kwargs)
  File "C:\Users\Karthikeyan\anaconda3\lib\site-packages\ray\util\tracing\tracing_helper.py", line 451, in _resume_span
    return method(self, *_args, **_kwargs)
  File "C:\Users\Karthikeyan\anaconda3\lib\site-packages\ray\rllib\agents\trainer.py", line 746, in __init__
    super().__init__(config, logger_creator, remote_checkpoint_dir,
  File "C:\Users\Karthikeyan\anaconda3\lib\site-packages\ray\tune\trainable.py", line 124, in __init__
    self.setup(copy.deepcopy(self.config))
  File "C:\Users\Karthikeyan\anaconda3\lib\site-packages\ray\util\tracing\tracing_helper.py", line 451, in _resume_span
    return method(self, *_args, **_kwargs)
  File "C:\Users\Karthikeyan\anaconda3\lib\site-packages\ray\rllib\agents\trainer.py", line 822, in setup
    self.workers = self._make_workers(
  File "C:\Users\Karthikeyan\anaconda3\lib\site-packages\ray\util\tracing\tracing_helper.py", line 451, in _resume_span
    return method(self, *_args, **_kwargs)
  File "C:\Users\Karthikeyan\anaconda3\lib\site-packages\ray\rllib\agents\trainer.py", line 1995, in _make_workers
    return WorkerSet(
  File "C:\Users\Karthikeyan\anaconda3\lib\site-packages\ray\rllib\evaluation\worker_set.py", line 101, in __init__
    remote_spaces = ray.get(self.remote_workers(
  File "C:\Users\Karthikeyan\anaconda3\lib\site-packages\ray\_private\client_mode_hook.py", line 105, in wrapper
    return func(*args, **kwargs)
  File "C:\Users\Karthikeyan\anaconda3\lib\site-packages\ray\worker.py", line 1765, in get
    raise value
  File "python\ray\_raylet.pyx", line 774, in ray._raylet.task_execution_handler
  File "python\ray\_raylet.pyx", line 595, in ray._raylet.execute_task
  File "python\ray\_raylet.pyx", line 737, in ray._raylet.execute_task
ray.exceptions.RayActorError: The actor died because of an error raised in its creation task, [36mray::RolloutWorker.__init__()[39m (pid=20508, ip=127.0.0.1, repr=<ray.rllib.evaluation.rollout_worker.RolloutWorker object at 0x000001CFCBB2B760>)
  File "python\ray\_raylet.pyx", line 640, in ray._raylet.execute_task
  File "python\ray\_raylet.pyx", line 644, in ray._raylet.execute_task
  File "python\ray\_raylet.pyx", line 593, in ray._raylet.execute_task.function_executor
  File "C:\Users\Karthikeyan\anaconda3\lib\site-packages\ray\_private\function_manager.py", line 648, in actor_method_executor
    return method(__ray_actor, *args, **kwargs)
  File "C:\Users\Karthikeyan\anaconda3\lib\site-packages\ray\util\tracing\tracing_helper.py", line 451, in _resume_span
    return method(self, *_args, **_kwargs)
  File "C:\Users\Karthikeyan\anaconda3\lib\site-packages\ray\rllib\evaluation\rollout_worker.py", line 458, in __init__
    self.env = env_creator(copy.deepcopy(self.env_context))
  File "C:\Users\Karthikeyan\anaconda3\lib\site-packages\ray\rllib\agents\trainer.py", line 2629, in <lambda>
    register_env(name, lambda cfg: env_object(cfg))
  File "C:\Users\Karthikeyan\Desktop\Github\Master-Thesis\Main_Folder\11_EMS_RL\Env_custom.py", line 71, in __init__
    self.max_load=(self.df['Load'].max())*1.2
KeyError: 'Load'

